<?xml version="1.0"?>
<robot name="umirobot_l1">
    <link name="robot_base">
        <inertial>
            <origin rpy="-3.141593 3.141593 -3.141593" xyz="0.000000 0.000000 0.000000" />
            <inertia ixx="1.0" ixz="0.0" ixy="0.0" izz="1.0" iyz="0.0" iyy="1.0" />
            <mass value="100.0" />
        </inertial>
        <collision name="umirobot_l1">
            <origin rpy="-3.141593 3.141593 -3.141593" xyz="0.000000 0.000000 0.000000" />
            <geometry>
                <mesh filename="file:///Users/francesco/Desktop/pingpong/urdf/paddle/braccioConRacket_robot_base_coll_1.dae" />
            </geometry>
        </collision>
        <visual name="umirobot_l1">
            <origin rpy="-3.141593 3.141593 -3.141593" xyz="0.000000 0.000000 0.000000" />
            <geometry>
                <mesh filename="file:///Users/francesco/Desktop/pingpong/urdf/paddle/braccioConRacket_robot_base_vis_1.dae" />
            </geometry>
            <material name="robot_base_material">
                <color rgba="1.000000 1.000000 1.000000 1.0" />
            </material>
        </visual>
    </link>
    <joint name="Revolute_joint" type="continuous">
        <axis xyz="0 0 1" />
        <parent link="robot_base" />
        <child link="umirobot_l2_cover" />
        <origin rpy="-3.141593 3.141593 -3.141593" xyz="-0.100000 0.000000 0.300000" />
    </joint>
    <link name="umirobot_l2_cover">
        <inertial>
            <origin rpy="0.000000 3.141593 -3.141593" xyz="0.100000 0.000000 0.700000" />
            <inertia ixx="0.01" ixz="0.0" ixy="0.0" izz="0.01" iyz="0.0" iyy="0.01" />
            <mass value="1.0" />
        </inertial>
        <collision name="umirobot_l2_cover">
            <origin rpy="0.000000 3.141593 -3.141593" xyz="0.100000 0.000000 0.700000" />
            <geometry>
                <mesh filename="file:///Users/francesco/Desktop/pingpong/urdf/paddle/braccioConRacket_umirobot_l2_cover_coll_1.dae" />
            </geometry>
        </collision>
        <visual name="umirobot_l2_cover">
            <origin rpy="0.000000 3.141593 -3.141593" xyz="0.100000 0.000000 0.700000" />
            <geometry>
                <mesh filename="file:///Users/francesco/Desktop/pingpong/urdf/paddle/braccioConRacket_umirobot_l2_cover_vis_1.dae" />
            </geometry>
            <material name="umirobot_l2_cover_material">
                <color rgba="1.000000 1.000000 1.000000 1.0" />
            </material>
        </visual>
    </link>
    <joint name="joint2" type="revolute">
        <axis xyz="0 0 1" />
        <limit velocity="6.28318530718" effort="20.5" upper="1.570796326795" lower="-1.570796326795" />
        <parent link="umirobot_l2_cover" />
        <child link="umirobot_l3" />
        <origin rpy="-1.570796 3.141593 -3.141593" xyz="0.000000 0.075000 0.550000" />
    </joint>
    <link name="umirobot_l3">
        <inertial>
            <origin rpy="0.000000 3.141593 -0.000000" xyz="0.000000 0.450000 -0.225000" />
            <inertia ixx="0.01" ixz="0.0" ixy="0.0" izz="0.01" iyz="0.0" iyy="0.01" />
            <mass value="1.0" />
        </inertial>
        <collision name="umirobot_l3">
            <origin rpy="0.000000 3.141593 -0.000000" xyz="0.000000 0.450000 -0.225000" />
            <geometry>
                <mesh filename="file:///Users/francesco/Desktop/pingpong/urdf/paddle/braccioConRacket_umirobot_l3_coll_1.dae" />
            </geometry>
        </collision>
        <visual name="umirobot_l3">
            <origin rpy="0.000000 3.141593 -0.000000" xyz="0.000000 0.450000 -0.225000" />
            <geometry>
                <mesh filename="file:///Users/francesco/Desktop/pingpong/urdf/paddle/braccioConRacket_umirobot_l3_vis_1.dae" />
            </geometry>
            <material name="umirobot_l3_material">
                <color rgba="1.000000 1.000000 1.000000 1.0" />
            </material>
        </visual>
    </link>
    <joint name="Revolute_joint_2" type="revolute">
        <axis xyz="0 0 1" />
        <limit velocity="6.28318530718" effort="20.5" upper="0.0" lower="-1.570796326795" />
        <parent link="umirobot_l3" />
        <child link="umirobot_l4" />
        <origin rpy="3.141593 3.141593 3.141593" xyz="-0.000000 0.800000 -0.175000" />
    </joint>
    <link name="umirobot_l4">
        <inertial>
            <origin rpy="3.141593 3.141593 -3.141593" xyz="0.450000 0.000000 -0.000000" />
            <inertia ixx="0.01" ixz="0.0" ixy="0.0" izz="0.01" iyz="0.0" iyy="0.01" />
            <mass value="1.0" />
        </inertial>
        <collision name="umirobot_l4">
            <origin rpy="3.141593 3.141593 -3.141593" xyz="0.450000 0.000000 -0.000000" />
            <geometry>
                <mesh filename="file:///Users/francesco/Desktop/pingpong/urdf/paddle/braccioConRacket_umirobot_l4_coll_1.dae" />
            </geometry>
        </collision>
        <visual name="umirobot_l4">
            <origin rpy="3.141593 3.141593 -3.141593" xyz="0.450000 0.000000 -0.000000" />
            <geometry>
                <mesh filename="file:///Users/francesco/Desktop/pingpong/urdf/paddle/braccioConRacket_umirobot_l4_vis_1.dae" />
            </geometry>
            <material name="umirobot_l4_material">
                <color rgba="1.000000 1.000000 1.000000 1.0" />
            </material>
        </visual>
    </link>
    <joint name="Revolute_joint_3" type="continuous">
        <axis xyz="0 0 1" />
        <parent link="umirobot_l4" />
        <child link="Racket" />
        <origin rpy="1.570796 3.141593 1.570796" xyz="1.100000 -0.150000 0.100000" />
    </joint>
    <link name="Racket">
        <visual name="Racket">
            <origin rpy="-0.000000 3.141593 1.570796" xyz="-0.000000 -0.000000 0.175000" />
            <geometry>
                <mesh filename="file:///Users/francesco/Desktop/pingpong/urdf/paddle/braccioConRacket_Racket_vis_1.dae" />
            </geometry>
            <material name="Racket_material">
                <color rgba="1.000000 1.000000 1.000000 1.0" />
            </material>
        </visual>
    </link>
</robot>
