<?xml version="1.0"?>
<robot name="umirobot_l1">
    <link name="robot_base">
        <inertial>
            <origin xyz="0.000000 0.000000 0.000000" rpy="-3.141593 3.141593 -3.141593" />
            <inertia izz="1.0" ixy="0.0" ixz="0.0" iyz="0.0" iyy="1.0" ixx="1.0" />
            <mass value="100.0" />
        </inertial>
        <collision name="umirobot_l1">
            <origin xyz="0.000000 0.000000 0.000000" rpy="-3.141593 3.141593 -3.141593" />
            <geometry>
                <mesh filename="file:///Users/francesco/Desktop/pingpong/urdf/braccioLight/piece1.stl" scale="0.01 0.01 0.01"/>
            </geometry>
        </collision>
        <visual name="umirobot_l1">
            <origin xyz="0.000000 0.000000 0.000000" rpy="-3.141593 3.141593 -3.141593" />
            <geometry>
                <mesh filename="file:///Users/francesco/Desktop/pingpong/urdf/braccioLight/piece1.stl" scale="0.01 0.01 0.01"/>
            </geometry>
            <material name="robot_base_material">
                <color rgba="1.000000 0.600000 0.000000 1.0" />
            </material>
        </visual>
    </link>
    <joint name="Revolute_joint" type="continuous">
        <axis xyz="0 0 1" />
        <parent link="robot_base" />
        <child link="umirobot_l2_cover" />
        <origin xyz="-0.100000 -0.000000 0.600000" rpy="-3.141593 3.141593 -3.141593" />
    </joint>
    <link name="umirobot_l2_cover">
        <inertial>
            <origin xyz="0.100000 0.000000 0.400000" rpy="0.000000 3.141593 -3.141593" />
            <inertia izz="0.01" ixy="0.0" ixz="0.0" iyz="0.0" iyy="0.01" ixx="0.01" />
            <mass value="1.0" />
        </inertial>
        <collision name="umirobot_l2_cover">
            <origin xyz="0.100000 0.000000 0.400000" rpy="0.000000 3.141593 -3.141593" />
            <geometry>
                <mesh filename="file:///Users/francesco/Desktop/pingpong/urdf/braccioLight/piece2.stl" scale="0.01 0.01 0.01"/>
            </geometry>
        </collision>
        <visual name="umirobot_l2_cover">
            <origin xyz="0.100000 0.000000 0.400000" rpy="0.000000 3.141593 -3.141593" />
            <geometry>
               <mesh filename="file:///Users/francesco/Desktop/pingpong/urdf/braccioLight/piece2.stl" scale="0.01 0.01 0.01"/>
            </geometry>
            <material name="umirobot_l2_cover_material">
                <color rgba="1.000000 1.000000 1.000000 1.0" />
            </material>
        </visual>
    </link>
    <joint name="joint2" type="revolute">
        <axis xyz="0 0 1" />
        <limit upper="1.570796326795" lower="-1.570796326795" velocity="6.28318530718" effort="20.5" />
        <parent link="umirobot_l2_cover" />
        <child link="umirobot_l3" />
        <origin xyz="-0.000000 0.075000 0.200000" rpy="-1.570796 3.141593 3.141593" />
    </joint> 
    <link name="umirobot_l3">
        <inertial>
            <origin xyz="0.000000 1.0000 -0.225000" rpy="1.570796 -3.141593 0" />
            <inertia izz="0.01" ixy="0.0" ixz="0.0" iyz="0.0" iyy="0.01" ixx="0.01" />
            <mass value="1.0" />
        </inertial>
        <collision name="umirobot_l3">
            <origin xyz="0.000000 1.0000 -0.225000" rpy="1.570796 -3.141593 0" />
            <geometry>
                <mesh filename="file:///Users/francesco/Desktop/pingpong/urdf/braccioLight/piece3.stl" scale="0.01 0.01 0.01"/>
            </geometry>
        </collision>
        <visual name="umirobot_l3">
            <origin xyz="0.000000 1.0000 -0.225000" rpy="1.570796 -3.141593 0" />
            <geometry>
                <mesh filename="file:///Users/francesco/Desktop/pingpong/urdf/braccioLight/piece3.stl" scale="0.01 0.01 0.01"/>
            </geometry>
            <material name="umirobot_l3_material">
                <color rgba="1.000000 0.600000 0.000000 1.0" />
            </material>
        </visual>
    </link>
    <joint name="Revolute_joint_2" type="revolute">
        <axis xyz="0 0 1" />
        <limit upper="1.570796326795" lower="-1.570796326795" velocity="6.28318530718" effort="20.5" />
        <parent link="umirobot_l3" />
        <child link="umirobot_l4" />
        <origin xyz="-0.000000 0.800000 -0.175000" rpy="3.141593 3.141593 3.141593" />
    </joint>
    <link name="umirobot_l4">
        <inertial>
            <origin xyz="-0.75 -1.400000 0.0" rpy="3.141593 3.141593 3.141593" />
            <inertia izz="0.01" ixy="0.0" ixz="0.0" iyz="0.0" iyy="0.01" ixx="0.01" />
            <mass value="1.0" />
        </inertial>
        <collision name="umirobot_l4">
            <origin xyz="-0.75 -1.400000 0.0" rpy="3.141593 3.141593 3.141593" />
            <geometry>
                <mesh filename="file:///Users/francesco/Desktop/pingpong/urdf/braccioLight/piece4.stl" scale="0.01 0.01 0.01" />
            </geometry>
        </collision>
        <visual name="umirobot_l4">
            <origin xyz="-0.75 -1.400000 0.0" rpy="3.141593 3.141593 3.141593" />
            <geometry>
                <mesh filename="file:///Users/francesco/Desktop/pingpong/urdf/braccioLight/piece4.stl" scale="0.01 0.01 0.01" />
            </geometry>
            <material name="umirobot_l4_material">
                <color rgba="1.000000 1.000000 1.000000 1.0" />
            </material>
        </visual>
    </link>
    <joint type="revolute" name="Revolute_joint_3">
        <axis xyz="0 0 1" />
        <limit effort="20.5" upper="3.14" lower="0" velocity="6.28318530718" />
        <parent link="umirobot_l4" />
        <child link="end_effector" />
        <origin xyz="1.200000 0.020000 0.170000" rpy="-1.570796 3.141593 -1.570796" />
    </joint>
    <link name="end_effector">
        <inertial>
            <origin rpy="-1.570796 1.570796 0.000000" xyz="0.010000 -0.120000 0.250000" />
            <inertia iyy="0.01" iyz="0.0" ixx="0.01" izz="0.01" ixz="0.0" ixy="0.0" />
            <mass value="1.0" />
        </inertial>
        <collision name="end_effector">
            <origin rpy="1.570796 -1.570796 0.000000" xyz="0.070000 0.756776 -0.563749" />
            <geometry>
                <mesh filename="file:///Users/francesco/Desktop/pingpong/urdf/braccioLight/endEffector.stl" scale="0.5 0.5 0.5"/>
            </geometry>
        </collision>
        <visual name="end_effector">
            <origin rpy="1.570796 -1.570796 0.000000" xyz="0.070000 0.756776 -0.563749" />
            <geometry>
                <mesh filename="file:///Users/francesco/Desktop/pingpong/urdf/braccioLight/endEffector.stl" scale="0.5 0.5 0.5"/>
            </geometry>
            <material name="end_effector_material">
                <color rgba="1.000000 1.000000 1.000000 1.0" />
            </material>
        </visual>
    </link>  
</robot>

